<?xml version="1.0" ?>
<!-- =================================================================================== -->
<!-- |    This document was autogenerated by xacro from /home/ipa-hsd/projects/kogrob2/urdf/urdf2_ws/src/schunk_io_driver/schunk_egp40_description/urdf/schunk_egp40.urdf.xacro | -->
<!-- |    EDITING THIS FILE BY HAND IS NOT RECOMMENDED                                 | -->
<!-- =================================================================================== -->
<robot name="schunk_egp40">
  <link name="world"/>
  <!-- Specify some standard inertial calculations https://en.wikipedia.org/wiki/List_of_moments_of_inertia -->
  <!-- These make use of xacro's mathematical functionality -->
  <material name="blue">
    <color rgba="0 0.2 1 1"/>
  </material>
  <material name="green">
    <color rgba="0 0.9 0.3 1"/>
  </material>
  <material name="white">
    <color rgba="1 1 1 1"/>
  </material>
  <!--Main gripper-->
  <link name="schunk_egp40_body_link">
    <visual>
      <geometry>
        <mesh filename="package://prbt_cell_description/meshes/schunk_egp40_body.STL" scale="0.001 0.001 0.001"/>
      </geometry>
      <origin rpy="1.5707963267948966 0 0" xyz="-0.02 0.013 -0.03655"/>
      <material name="green"/>
    </visual>
    <collision>
      <geometry>
        <mesh filename="package://prbt_cell_description/meshes/schunk_egp40_body.STL" scale="0.001 0.001 0.001"/>
      </geometry>
      <origin rpy="1.5707963267948966 0 0" xyz="-0.02 0.013 -0.03655"/>
    </collision>
    <inertial>
      <origin rpy="1.5707963267948966 0 0" xyz="-0.02 0.013 -0.03655"/>
      <mass value="0.5"/>
      <inertia ixx="0.0002508170833333333" ixy="0.0" ixz="0.0" iyy="0.00028931708333333327" iyz="0.0" izz="9.483333333333334e-05"/>
    </inertial>
  </link>
  <!--Pincer block 1-->
  <link name="schunk_egp40_finger_left_link">
    <visual>
      <geometry>
        <mesh filename="package://prbt_cell_description/meshes/schunk_finger_left.STL" scale="0.001 0.001 0.001"/>
      </geometry>
      <origin rpy="1.5707963267948966 0 0" xyz="-0.02 0.008 -0.07925"/>
      <material name="white"/>
    </visual>
    <collision>
      <geometry>
        <mesh filename="package://prbt_cell_description/meshes/schunk_finger_left.STL" scale="0.001 0.001 0.001"/>
      </geometry>
      <origin rpy="1.5707963267948966 0 0" xyz="-0.02 0.008 -0.07925"/>
    </collision>
    <inertial>
      <origin rpy="1.5707963267948966 0 0" xyz="-0.02 0.008 -0.07925"/>
      <mass value="0.1"/>
      <inertia ixx="3.394083333333333e-06" ixy="0.0" ixz="0.0" iyy="1.4594083333333333e-05" iyz="0.0" izz="1.5466666666666665e-05"/>
    </inertial>
  </link>
  <!--Pincer block 2-->
  <link name="schunk_egp40_finger_right_link">
    <visual>
      <geometry>
        <mesh filename="package://prbt_cell_description/meshes/schunk_finger_right.STL" scale="0.001 0.001 0.001"/>
      </geometry>
      <origin rpy="1.5707963267948966 0 0" xyz="-0.02 0.008 -0.07925"/>
      <material name="blue"/>
    </visual>
    <collision>
      <geometry>
        <mesh filename="package://prbt_cell_description/meshes/schunk_finger_right.STL" scale="0.001 0.001 0.001"/>
      </geometry>
      <origin rpy="1.5707963267948966 0 0" xyz="-0.02 0.008 -0.07925"/>
    </collision>
    <inertial>
      <origin rpy="1.5707963267948966 0 0" xyz="-0.02 0.008 -0.07925"/>
      <mass value="0.1"/>
      <inertia ixx="3.394083333333333e-06" ixy="0.0" ixz="0.0" iyy="1.4594083333333333e-05" iyz="0.0" izz="1.5466666666666665e-05"/>
    </inertial>
  </link>
  <!-- Virtual link for visualizytion and planning-->
  <link name="tool_tip"/>
  <!-- Joints-->
  <joint name="schunk_egp40_body_joint" type="fixed">
    <parent link="schunk_egp40_base_link"/>
    <child link="schunk_egp40_body_link"/>
    <origin rpy="0.0 0.0 0.0" xyz="0.0 0.0 0.05155"/>
  </joint>
  <joint name="schunk_egp40_finger_left_joint" type="prismatic">
    <parent link="schunk_egp40_body_link"/>
    <child link="schunk_egp40_finger_left_link"/>
    <origin rpy="0.0 0.0 0.0" xyz="0.0 0.0 0.0427"/>
    <!-- the motion of the pincer is along the X axis -->
    <axis xyz="1 0 0"/>
    <!-- the motion of the pincer is limited to the half of the gripper body length -->
    <limit effort="100" lower="-0.0025" upper="0.0025" velocity="100"/>
  </joint>
  <joint name="schunk_egp40_finger_right_joint" type="prismatic">
    <parent link="schunk_egp40_body_link"/>
    <child link="schunk_egp40_finger_right_link"/>
    <origin rpy="0.0 0.0 0.0" xyz="0.0 0.002 0.0427"/>
    <!-- the motion of the pincer is along the X axis -->
    <axis xyz="1 0 0"/>
    <!-- the motion of the pincer is limited to the half of the gripper body length -->
    <limit effort="100" lower="0.0025" upper="-0.0025" velocity="100"/>
  </joint>
  <joint name="schunk_egp40_tip_joint" type="fixed">
    <parent link="schunk_egp40_base_link"/>
    <child link="tool_tip"/>
    <origin rpy="0.0 0.0 0.0" xyz="0 0 0.0884"/>
  </joint>
  <joint name="schunk_egp40_base_joint" type="fixed">
    <parent link="world"/>
    <child link="schunk_egp40_base_link"/>
    <origin rpy="0 0 0" xyz="0 0 0"/>
  </joint>
</robot>
